Workbook

Sheet INDEX
B2: #VALUE!
B4: DCF VALUATION & FINANCIAL ANALYSIS DASHBOARD
B6: Current Share Price | F6: DCF Value / Share | J6: Discount / (Premium) | N6: WACC
B7: {=_FV(B2,"Open")} -> 1158.1 | F7: =Valuation!$J$37 -> 1028.5768 | J7: =Valuation!J39 -> -0.14993657 | N7: =Valuation!C45 -> 0.12882212
B10: MODEL NAVIGATION | F10: VALUATION SNAPSHOT | J10: KEY DCF ASSUMPTIONS
B11: =HYPERLINK("#'Assumptions'!A1","Assumptions") -> Assumptions | C11: Working | D11: Financial Statements | F11: Enterprise / Operating Assets | G11: =Valuation!J31 -> 2746577.9 | J11: Risk-Free Rate | K11: =Assumptions!C102 -> 0.071
B12: Income Statement | C12: Balance Sheet | D12: Cash Flow | F12: Equity Value | G12: =Valuation!J35 -> 2719556.9 | J12: Beta | K12: =Assumptions!C104 -> 0.92
B13: Valuation | C13: =HYPERLINK("#CCA!B2","CCA") -> CCA | D13: Ratio | F13: Shares Outstanding | G13: =Valuation!J36 -> 2644 | J13: Market Risk Premium | K13: =Assumptions!C103 -> 0.065
J14: Terminal Growth | K14: =Assumptions!C109 -> 0.04
B16: Revenue & EBITDA Trend | J16: PROFITABILITY MARGINS
B27: ROC AND ROCE | J27: Valuation Summary
J28: Valuation Method | K28: Implied Value / Share | N28: Reference
J29: DCF | K29: =Valuation!J37 -> 1028.5768 | N29: Primary DCF valuation
J30: EV / Revenue | K30: =CCA!G62 -> 2466.8951 | N30: Peer median multiple
J31: EV / EBITDA | K31: =CCA!G63 -> 685.48681 | N31: Peer median multiple
J32: EV / EBIT | K32: =CCA!G64 -> 589.84843 | N32: Peer median multiple
J33: P / E | K33: =CCA!G65 -> 581.65017 | N33: Peer median multiple
J35: WORKING CAPITAL EFFICIENCY
B38: FCFF VS FCFE
B48: COMPANY OVERVIEW | I48: Investment & Financial Overview
B49: United Breweries Limited (UBL) is one of India’s leading beer companies and is best known for its flagship Kingfisher brand. The company operates in the alcoholic beverages industry, with its business primarily focused on beer. UBL has an established distribution network and a strong presence across the Indian market. | H49: This dashboard presents a DCF-based valuation and financial analysis of UBL, covering historical performance from FY2021–FY2025 and forecasts through FY2035. The analysis evaluates revenue growth, profitability, liquidity, leverage, working-capital efficiency and return ratios. The valuation section uses FCFF/DCF methodology, supported by WACC, terminal growth and sensitivity analysis. Relative valuation through EV/Revenue, EV/EBITDA, EV/EBIT and P/E multiples is also presented to provide a comparison with selected listed peers.
P52: =[1]FS!R4 -> FY2035
P53: =[1]FS!R8 -> 0
P54: =[1]FS!R26 -> 0
P55: =[1]FS!R18 -> 0
P56: =P54+P55 -> 0
B61: Key Takeaway
B62: Revenue growth normalizes toward 5% in the later forecast years, reflecting a more mature growth profile.
B63: EBITDA margin expands from 4.4% in FY2025A to 14.4% by FY2035E, indicating significant operating leverage.
B64: EBIT margin improves from 3.2% in FY2025A to 12.9% by FY2035E, supported by margin expansion and operating efficiencies.
B65: PAT margin increases from 2.3% in FY2025A to 8.9% by FY2035E, reflecting stronger operating profitability.
B66: Current Ratio improves from 1.41x in FY2025A to 2.99x by FY2035E, indicating strengthening liquidity.
B67: Debt/Equity declines from 0.14x in FY2025A to 0.06x by FY2035E, reflecting limited reliance on debt.
B68: Interest Coverage increases from 66.17x in FY2025A to 154.46x by FY2035E as EBIT grows faster than finance costs.
B69: Cash Conversion Cycle remains elevated at approximately 95 days during the forecast period, indicating continued working-capital requirements.
B70: ROE increases from 10.1% in FY2025A to approximately 25% in the later forecast years, reflecting stronger earnings generation.
B71: ROCE rises from 13.9% in FY2025A to approximately 38% during the forecast period, indicating improved returns on capital employed.
B72: FCFF increases from ₹59,940 lakh in FY2026E to ₹296,032 lakh by FY2035E, supporting higher operating cash generation.
... B108: FILL THE INPUT TABLES BELOW WITH YOUR FINAL HISTORICAL + FORECAST VALUES. THE CHARTS ABOVE WILL UPDATE AUTOMATICALLY.

Sheet CHARTS
A1: United Breweries Limited
A2: Working
C3: Period Start | H3: 43922 | I3: 44287 | J3: 44652 | K3: 45017 | L3: 45383 | M3: 45748 | N3: 46113 | O3: 46478 | P3: 46844 | Q3: 47209 | R3: 47574 | S3: 47939 | T3: 48305 | U3: 48670 | V3: 49035
C4: Period End | H4: 44286 | I4: 44651 | J4: 45016 | K4: 45382 | L4: 45747 | M4: 46112 | N4: 46477 | O4: 46843 | P4: 47208 | Q4: 47573 | R4: 47938 | S4: 48304 | T4: 48669 | U4: 49034 | V4: 49399
C5: Period Type | H5: Historical | I5: Historical | J5: Historical | K5: Historical | L5: Historical | M5: Forecast | N5: Forecast | O5: Forecast | P5: Forecast | Q5: Forecast | R5: Forecast | S5: Forecast | T5: Forecast | U5: Forecast | V5: Forecast
C6: Days | H6: =H4-H3+1 -> 365 | I6: =I4-I3+1 -> 365 | J6: =J4-J3+1 -> 365 | K6: =K4-K3+1 -> 366 | L6: =L4-L3+1 -> 365 | M6: =M4-M3+1 -> 365 | N6: =N4-N3+1 -> 365 | O6: =O4-O3+1 -> 366 | ... V6: =V4-V3+1 -> 365
A7: Timing
A9: Model Start Date | B9: Date | C9: 43922
A10: Months in a period | B10: # | C10: 12
A11: Start of Forecast Period | B11: Date | C11: 45748
A12: Number of Forecast Period | B12: # | C12: 10
A15: Revenue
A16: Revenue from Contracts with Customers
A17: Revenue from contracts with customers (including excise duty) | B17: ₹ Lakhs | H17: ='Income Statement-Historic'!C12 -> 1018576 | I17: ='Income Statement-Historic'!D12 -> 1312392 | J17: ='Income Statement-Historic'!E12 -> 1665109 | K17: ='Income Statement-Historic'!F12 -> 1837953 | L17: ='Income Statement-Historic'!G12 -> 1940854 | M17: =L17*(1+M18) -> 2076713.8 | N17: =M17*(1+N18) -> 2222083.7 | O17: =N17*(1+O18) -> 2366519.2 | P17: =O17*(1+P18) -> 2520342.9 | Q17: =P17*(1+Q18) -> 2671563.5 | R17: =Q17*(1+R18) -> 2831857.3 | S17: =R17*(1+S18) -> 2987609.5 | T17: =S17*(1+T18) -> 3151928 | ... V17: =U17*(1+V18) -> 3475000.6
A18: Revenue Growth Rate | B18: % | I18: =I17/H17-1 -> 0.28845761 | J18: =J17/I17-1 -> 0.26875888 | K18: =K17/J17-1 -> 0.10380341 | L18: =L17/K17-1 -> 0.055986742 | M18: 0.07 | N18: 0.07 | O18: 0.065 | P18: 0.065 | Q18: 0.06 | R18: 0.06 | S18: 0.055 | T18: 0.055 | U18: 0.05 | V18: 0.05
A19: Other income | B19: ₹ Lakhs | H19: ='Income Statement-Historic'!C13 -> 5025 | I19: ='Income Statement-Historic'!D13 -> 2979 | J19: ='Income Statement-Historic'!E13 -> 4943 | K19: ='Income Statement-Historic'!F13 -> 7374 | L19: ='Income Statement-Historic'!G13 -> 3590 | M19: =M17*M20 -> 6659.4424 | N19: =N17*N20 -> 7125.6034 | O19: =O17*O20 -> 7588.7676 | P19: =P17*P20 -> 8082.0375 | Q19: =Q17*Q20 -> 8566.9598 | R19: =R17*R20 -> 9080.9774 | S19: =S17*S20 -> 9580.4311 | T19: =T17*T20 -> 10107.355 | ... V19: =V17*V20 -> 11143.359
A20: Other Income % of Revenue | B20: % | H20: =H19/H17 -> 0.0049333579 | I20: =I19/I17 -> 0.0022699011 | J20: =J19/J17 -> 0.0029685744 | K20: =K19/K17 -> 0.0040120721 | L20: =L19/L17 -> 0.0018497012 | M20: =AVERAGE(H20:L20) -> 0.0032067214 | N20: =$M$20 -> 0.0032067214 | O20: =$M$20 -> 0.0032067214 | P20: =$M$20 -> 0.0032067214 | Q20: =$M$20 -> 0.0032067214 | R20: =$M$20 -> 0.0032067214 | S20: =$M$20 -> 0.0032067214 | T20: =$M$20 -> 0.0032067214 | U20: =$M$20 -> 0.0032067214 | V20: =$M$20 -> 0.0032067214
A21: Total Revenue | H21: =SUM(H19,H17) -> 1023601 | I21: =SUM(I19,I17) -> 1315371 | J21: =SUM(J19,J17) -> 1670052 | K21: =SUM(K19,K17) -> 1845327 | L21: =SUM(L19,L17) -> 1944444 | M21: =SUM(M19,M17) -> 2083373.2 | N21: =SUM(N19,N17) -> 2229209.3 | O21: =SUM(O19,O17) -> 2374108 | ... V21: =SUM(V19,V17) -> 3486144
A23: Cost
A24: Cost of Sales
A25: Cost of materials consumed | B25: ₹ Lakhs | H25: ='Income Statement-Historic'!C17 -> 196516 | I25: ='Income Statement-Historic'!D17 -> 270729 | J25: ='Income Statement-Historic'!E17 -> 422476 | K25: ='Income Statement-Historic'!F17 -> 456755 | L25: ='Income Statement-Historic'!G17 -> 493673 | M25: =M17*M26 -> 480058.57 | N25: =N17*N26 -> 503389.42 | O25: =O17*O26 -> 509304.25 | P25: =P17*P26 -> 520712.66 | Q25: =Q17*Q26 -> 529877.21 | R25: =R17*R26 -> 539203.04 | S25: =S17*S26 -> 568859.21 | T25: =T17*T26 -> 600146.47 | ... V25: =V17*V26 -> 661661.48
A26: Cost as % of Revenue | B26: % of Revenue | H26: =H25/H17 -> 0.19293209 | I26: =I25/I17 -> 0.20628669 | J26: =J25/J17 -> 0.25372273 | K26: =K25/K17 -> 0.24851288 | L26: =L25/L17 -> 0.25435865 | M26: =AVERAGE(H26:L26) -> 0.23116261 | N26: =M26-(M26*2%) -> 0.22653936 | O26: =N26-(N26*5%) -> 0.21521239 | P26: =O26-(O26*4%) -> 0.20660389 | Q26: =P26-(P26*4%) -> 0.19833974 | R26: =Q26-(Q26*4%) -> 0.19040615 | S26: =R26 -> 0.19040615 | T26: =S26 -> 0.19040615 | U26: =T26 -> 0.19040615 | V26: =U26 -> 0.19040615
A27: Purchase of stock-in-trade / traded goods | B27: ₹ Lakhs | H27: ='Income Statement-Historic'!C18 -> 7371 | I27: ='Income Statement-Historic'!D18 -> 19582 | J27: ='Income Statement-Historic'!E18 -> 9247 | K27: ='Income Statement-Historic'!F18 -> 11825 | L27: ='Income Statement-Historic'!G18 -> 18174 | M27: =M17*M28 -> 18070.948 | N27: =N17*N28 -> 19335.914 | O27: =O17*O28 -> 20592.748 | P27: =P17*P28 -> 21931.277 | Q27: =Q17*Q28 -> 23247.154 | R27: =R17*R28 -> 24641.983 | S27: =S17*S28 -> 25997.292 | T27: =T17*T28 -> 27427.143 | ... V27: =V17*V28 -> 30238.425
A28: Cost as % of Revenue | B28: % of Revenue | H28: =H27/H17 -> 0.0072365734 | I28: =I27/I17 -> 0.014920847 | J28: =J27/J17 -> 0.0055533902 | K28: =K27/K17 -> 0.006433788 | L28: =L27/L17 -> 0.0093639192 | M28: =AVERAGE(H28:L28) -> 0.0087017035 | N28: =$M$28 -> 0.0087017035 | O28: =$M$28 -> 0.0087017035 | P28: =$M$28 -> 0.0087017035 | Q28: =$M$28 -> 0.0087017035 | R28: =$M$28 -> 0.0087017035 | S28: =$M$28 -> 0.0087017035 | T28: =$M$28 -> 0.0087017035 | U28: =$M$28 -> 0.0087017035 | V28: =$M$28 -> 0.0087017035
A29: Changes in inventories of finished goods, work-in-progress and stock-in-trade | B29: ₹ Lakhs | H29: ='Income Statement-Historic'!C19 -> -950 | I29: ='Income Statement-Historic'!D19 -> 2301 | J29: ='Income Statement-Historic'!E19 -> -5187 | K29: ='Income Statement-Historic'!F19 -> -3345 | L29: ='Income Statement-Historic'!G19 -> -4996 | M29: =M17*M30 -> -5345.72 | N29: =N17*N30 -> -5719.9204 | O29: =O17*O30 -> -6091.7152 | P29: =P17*P30 -> -6487.6767 | Q29: =Q17*Q30 -> -6876.9373 | R29: =R17*R30 -> -7289.5536 | S29: =S17*S30 -> -7690.479 | T29: =T17*T30 -> -8113.4553 | ... V29: =V17*V30 -> -8945.0845
A30: Changes in Inventories as % of Revenue | B30: % of Revenue | H30: =H29/H17 -> -0.00093267464 | I30: =I29/I17 -> 0.0017532871 | J30: =J29/J17 -> -0.0031151114 | K30: =K29/K17 -> -0.0018199595 | L30: =L29/L17 -> -0.0025741246 | M30: =L30 -> -0.0025741246 | N30: =M30 -> -0.0025741246 | O30: =N30 -> -0.0025741246 | P30: =O30 -> -0.0025741246 | Q30: =P30 -> -0.0025741246 | R30: =Q30 -> -0.0025741246 | S30: =R30 -> -0.0025741246 | T30: =S30 -> -0.0025741246 | ... V30: =U30 -> -0.0025741246
A31: Excise duty on sale of goods/products | B31: ₹ Lakhs | H31: ='Income Statement-Historic'!C20 -> 594267 | I31: ='Income Statement-Historic'!D20 -> 728548 | J31: ='Income Statement-Historic'!E20 -> 915117 | K31: ='Income Statement-Historic'!F20 -> 1025685 | L31: ='Income Statement-Historic'!G20 -> 1049345 | M31: =M17*M32 -> 1157503.3 | N31: =N17*N32 -> 1238528.5 | O31: =O17*O32 -> 1305842.5 | P31: =P17*P32 -> 1376815 | Q31: =Q17*Q32 -> 1444829.7 | R31: =R17*R32 -> 1516204.3 | S31: =S17*S32 -> 1583599.6 | T31: =T17*T32 -> 1653990.6 | ... V31: =V17*V32 -> 1787236.5
A32: Excise Duty as % of Revenue | B32: % of Revenue | H32: =H31/H17 -> 0.58342922 | I32: =I31/I17 -> 0.55512987 | J32: =J31/J17 -> 0.54958384 | K32: =K31/K17 -> 0.55805834 | L32: =L31/L17 -> 0.54066148 | M32: =AVERAGE(H32:L32) -> 0.55737255 | N32: =M32 -> 0.55737255 | O32: =N32-(N32*1%) -> 0.55179882 | P32: =O32-(O32*1%) -> 0.54628084 | Q32: =P32-(P32*1%) -> 0.54081803 | R32: =Q32-(Q32*1%) -> 0.53540985 | S32: =R32-(R32*1%) -> 0.53005575 | T32: =S32-(S32*1%) -> 0.52475519 | U32: =T32-(T32*1%) -> 0.51950764 | V32: =U32-(U32*1%) -> 0.51431256
A33: COGS | H33: =SUM(H25+H27+H29) -> 202937 | I33: =SUM(I25+I27+I29) -> 292612 | J33: =SUM(J25+J27+J29) -> 426536 | K33: =SUM(K25+K27+K29) -> 465235 | L33: =SUM(L25+L27+L29) -> 506851 | M33: =SUM(M25+M27+M29) -> 492783.8 | N33: =SUM(N25+N27+N29) -> 517005.42 | O33: =SUM(O25+O27+O29) -> 523805.28 | ... V33: =SUM(V25+V27+V29) -> 682954.82
A35: Employee Costs
A36: Employee benefits expense | B36: ₹ Lakhs | H36: ='Income Statement-Historic'!C21 -> 48549 | I36: ='Income Statement-Historic'!D21 -> 52312 | J36: ='Income Statement-Historic'!E21 -> 41183 | K36: ='Income Statement-Historic'!F21 -> 45210 | L36: ='Income Statement-Historic'!G21 -> 52180 | M36: =M17*M37 -> 68008.077 | N36: =N17*N37 -> 72768.642 | O36: =O17*O37 -> 77498.604 | P36: =P17*P37 -> 82536.013 | Q36: =Q17*Q37 -> 87488.174 | R36: =R17*R37 -> 92737.464 | S36: =S17*S37 -> 97838.025 | T36: =T17*T37 -> 103219.12 | ... V36: =V17*V37 -> 113799.08
A37: Employee Benefits Expense as % of Revenue | B37: % of Revenue | H37: =H36/H17 -> 0.047663601 | I37: =I36/I17 -> 0.039860042 | J37: =J36/J17 -> 0.024732915 | K37: =K36/K17 -> 0.024598017 | L37: =L36/L17 -> 0.026885072 | M37: =AVERAGE(H37:L37) -> 0.03274793 | N37: =M37 -> 0.03274793 | O37: =N37 -> 0.03274793 | P37: =O37 -> 0.03274793 | Q37: =P37 -> 0.03274793 | R37: =Q37 -> 0.03274793 | S37: =R37 -> 0.03274793 | T37: =S37 -> 0.03274793 | U37: =T37 -> 0.03274793 | V37: =U37 -> 0.03274793
A38: Contract employee expense | B38: ₹ Lakhs | H38: ='Income Statement-Historic'!C22 -> — | I38: ='Income Statement-Historic'!D22 -> — | J38: ='Income Statement-Historic'!E22 -> 18368 | K38: ='Income Statement-Historic'!F22 -> 19525 | L38: ='Income Statement-Historic'!G22 -> 19666 | M38: =M17*M39 -> 22004.163 | N38: =N17*N39 -> 23544.454 | O38: =O17*O39 -> 25074.844 | P38: =P17*P39 -> 26704.709 | Q38: =Q17*Q39 -> 28306.991 | R38: =R17*R39 -> 30005.411 | S38: =S17*S39 -> 31655.708 | T38: =T17*T39 -> 33396.772 | ... V38: =V17*V39 -> 36819.941
A39: Contract Employee Expense as % of Revenue | B39: % of Revenue | J39: =J38/J17 -> 0.01103111 | K39: =K38/K17 -> 0.010623231 | L39: =L38/L17 -> 0.010132653 | M39: =AVERAGE(J39:L39) -> 0.010595665 | N39: =M39 -> 0.010595665 | O39: =N39 -> 0.010595665 | P39: =O39 -> 0.010595665 | Q39: =P39 -> 0.010595665 | R39: =Q39 -> 0.010595665 | S39: =R39 -> 0.010595665 | T39: =S39 -> 0.010595665 | U39: =T39 -> 0.010595665 | V39: =U39 -> 0.010595665
A41: Other Operating Expenses
A42: Other expenses | B42: ₹ Lakhs | H42: ='Income Statement-Historic'!C25 -> 134717 | I42: ='Income Statement-Historic'!D25 -> 169258 | J42: ='Income Statement-Historic'!E25 -> 202282 | K42: ='Income Statement-Historic'!F25 -> 212679 | L42: ='Income Statement-Historic'!G25 -> 228731 | M42: =M17*M43 -> 255966.52 | N42: =N17*N43 -> 273884.18 | O42: =O17*O43 -> 288769.78 | P42: =P17*P43 -> 304464.42 | Q42: =Q17*Q43 -> 319504.96 | R42: =R17*R43 -> 335288.51 | S42: =S17*S43 -> 343117.5 | T42: =T17*T43 -> 351129.29 | ... V42: =V17*V43 -> 364241.25
A43: Other Expenses as % of Revenue | B43: % of Revenue | H43: =H42/H17 -> 0.13226014 | I43: =I42/I17 -> 0.12896909 | J43: =J42/J17 -> 0.12148274 | K43: =K42/K17 -> 0.11571515 | L43: =L42/L17 -> 0.1178507 | M43: =AVERAGE(H43:L43) -> 0.12325556 | N43: =M43 -> 0.12325556 | O43: =N43-(N43*1%) -> 0.12202301 | P43: =O43-(O43*1%) -> 0.12080278 | Q43: =P43-(P43*1%) -> 0.11959475 | R43: =Q43-(Q43*1%) -> 0.1183988 | S43: =R43-(R43*3%) -> 0.11484684 | T43: =S43-(S43*3%) -> 0.11140143 | U43: =T43-(T43*3%) -> 0.10805939 | V43: =U43-(U43*3%) -> 0.10481761
A44: Finance Cost
A45: Finance Cost | B45: ₹ Lakhs | H45: ='Income Statement-Historic'!C23 -> 2267 | I45: ='Income Statement-Historic'!D23 -> 1478 | J45: ='Income Statement-Historic'!E23 -> 464 | K45: ='Income Statement-Historic'!F23 -> 689 | L45: ='Income Statement-Historic'!G23 -> 1286 | M45: =M46*M17 -> 1938.8088 | N45: =N46*N17 -> 2074.5254 | O45: =O46*O17 -> 2209.3696 | P45: =P46*P17 -> 2352.9786 | Q45: =Q46*Q17 -> 2494.1573 | R45: =R46*R17 -> 2643.8067 | S45: =S46*S17 -> 2789.2161 | T45: =T46*T17 -> 2942.623 | ... V45: =V46*V17 -> 3244.2418
A46: Finacne cost as % of Revenue | B46: % of Revenue | H46: =H45/H17 -> 0.0022256562 | I46: =I45/I17 -> 0.0011261879 | J46: =J45/J17 -> 0.00027866044 | K46: =K45/K17 -> 0.00037487357 | L46: =L45/L17 -> 0.00066259492 | M46: =AVERAGE(H46:L46) -> 0.00093359461 | N46: =M46 -> 0.00093359461 | O46: =N46 -> 0.00093359461 | P46: =O46 -> 0.00093359461 | Q46: =P46 -> 0.00093359461 | R46: =Q46 -> 0.00093359461 | S46: =R46 -> 0.00093359461 | T46: =S46 -> 0.00093359461 | U46: =T46 -> 0.00093359461 | V46: =U46 -> 0.00093359461
...

Sheet Balance Sheet- Historic
A1: United Breweries Limited
A2: Annual Report- Balance Sheet Consolidated
A9: Particulars | B9: Note | C9: FY2021 | D9: FY2022 | E9: FY2023 | F9: FY2024 | G9: FY2025
A10: Property, plant and equipment | C10: 192203 | D10: 189008 | E10: 183235 | F10: 176009 | G10: 173512
A11: Capital work-in-progress | C11: 12879 | D11: 10989 | E11: 7713 | F11: 17268 | G11: 25337
A12: Intangible assets | C12: 2098 | D12: 1638 | E12: 1223 | F12: 904 | G12: 737
A13: Goodwill on consolidation | C13: 645 | D13: 645 | E13: 645 | F13: 645 | G13: 645
A14: Investments | C14: 606 | D14: 835 | E14: 805 | F14: 797 | G14: 785
A15: Other financial assets | C15: 4711 | D15: 4816 | E15: 4676 | F15: 3937 | G15: 4498
A16: Income tax assets (net) | C16: 20395 | D16: 20199 | E16: 22138 | F16: 21135 | G16: 22596
A17: Deferred tax asset (net) | C17: 3497 | D17: 3844 | E17: 4501 | F17: 5293 | G17: 6674
A18: Other non-current assets | C18: 15826 | D18: 25044 | E18: 34458 | F18: 37802 | G18: 42203
A19: Total non-current assets | C19: =SUM(C10:C18) -> 252860 | D19: =SUM(D10:D18) -> 257018 | E19: =SUM(E10:E18) -> 259394 | F19: =SUM(F10:F18) -> 263790 | G19: =SUM(G10:G18) -> 276987
A20: Inventories | C20: 113668 | D20: 93581 | E20: 142781 | F20: 136874 | G20: 161643
A21: Trade receivables | C21: 139499 | D21: 125486 | E21: 140732 | F21: 231384 | G21: 286063
A22: Cash and cash equivalents | C22: 40970 | D22: 86260 | E22: 32986 | F22: 12915 | G22: 34192
A23: Bank balances | C23: 5958 | D23: 4708 | E23: 6543 | F23: 8505 | G23: 10096
A24: Other financial assets | C24: 84 | D24: 115 | E24: 104 | F24: 254 | G24: 389
A25: Other current assets | C25: 31689 | D25: 27275 | E25: 45013 | F25: 51122 | G25: 52423
A26: Total current assets | C26: =SUM(C20:C25) -> 331868 | D26: =SUM(D20:D25) -> 337425 | E26: =SUM(E20:E25) -> 368159 | F26: =SUM(F20:F25) -> 441054 | G26: =SUM(G20:G25) -> 544806
A27: Assets held for sale | C27: 488 | D27: 488 | E27: 486 | F27: 493 | G27: 486
A28: Total assets | C28: =SUM(C19,C26,C27) -> 585216 | D28: =SUM(D19,D26,D27) -> 594931 | E28: =SUM(E19,E26,E27) -> 628039 | F28: =SUM(F19,F26,F27) -> 705337 | G28: =SUM(G19,G26,G27) -> 822279
A30: Equity Share Capital | C30: 2644 | D30: 2644 | E30: 2644 | F30: 2644 | G30: 2644
A31: Other Equity | C31: 355584 | D31: 390868 | E31: 393845 | F31: 415190 | G31: 433748
A32: Equity attributable to owners of the parent | C32: =SUM(C30:C31) -> 358228 | D32: =SUM(D30:D31) -> 393512 | E32: =SUM(E30:E31) -> 396489 | F32: =SUM(F30:F31) -> 417834 | G32: =SUM(G30:G31) -> 436392
A33: Non-controlling interests (NCI) | C33: 375 | D33: 414 | E33: 461 | F33: 522 | G33: 572
A34: Total Equity | C34: =SUM(C32:C33) -> 358603 | D34: =SUM(D32:D33) -> 393926 | E34: =SUM(E32:E33) -> 396950 | F34: =SUM(F32:F33) -> 418356 | G34: =SUM(G32:G33) -> 436964
A36: Non-current Liabilities
A37: Borrowings | C37: 11524 | D37: 0 | E37: 0 | F37: 0 | G37: 0
A38: Lease Liabilities | C38: — | D38: 606 | E38: 1074 | F38: 1690 | G38: 3569
A39: Other Financial Liabilities | C39: 1109 | D39: 2497 | E39: 1845 | F39: 1461 | G39: 2040
A40: Provisions | C40: 160 | D40: 441 | E40: 424 | F40: 917 | G40: 1405
A41: Total Non-current Liabilities | C41: 12793 | D41: 3544 | E41: 3343 | F41: 4068 | G41: 7014
A43: Current Liabilities
A44: Borrowings | C44: 17 | D44: 0 | E44: 0 | F44: 7741 | G44: 57485
A45: Lease Liabilities | C45: — | D45: 368 | E45: 488 | F45: 772 | G45: 944
A46: Trade Payables — MSME | C46: 5205 | D46: 9158 | E46: 9530 | F46: 12566 | G46: 12693
A47: Trade Payables — Others | C47: 56603 | D47: 54642 | E47: 62168 | F47: 82279 | G47: 102262
A48: Other Financial Liabilities | C48: 68177 | D48: 55810 | E48: 77835 | F48: 86664 | G48: 100578
A49: Other Current Liabilities | C49: 74710 | D49: 67261 | E49: 67518 | F49: 83327 | G49: 94769
...

Sheet Income Statement-Historic
A1: United Breweries Limited
A2: Annual Report- Income Statement Consolidated
A10: Particulars | B10: Note | C10: FY2021 | D10: FY2022 | E10: FY2023 | F10: FY2024 | G10: FY2025
A11: INCOME
A12: Revenue from contracts with customers (including excise duty) | B12: 21/19/20 | C12: 1018576 | D12: 1312392 | E12: 1665109 | F12: 1837953 | G12: 1940854
A13: Other income | B13: 22/20/21 | C13: 5025 | D13: 2979 | E13: 4943 | F13: 7374 | G13: 3590
A14: Total Income | C14: =SUM(C12:C13) -> 1023601 | D14: =SUM(D12:D13) -> 1315371 | E14: =SUM(E12:E13) -> 1670052 | F14: =SUM(F12:F13) -> 1845327 | G14: =SUM(G12:G13) -> 1944444
A16: EXPENSES
A17: Cost of materials consumed | B17: 23/21/22 | C17: 196516 | D17: 270729 | E17: 422476 | F17: 456755 | G17: 493673
A18: Purchase of stock-in-trade / traded goods | B18: 24/22/23 | C18: 7371 | D18: 19582 | E18: 9247 | F18: 11825 | G18: 18174
A19: Changes in inventories of finished goods, WIP and stock-in-trade | B19: 25/23/24 | C19: -950 | D19: 2301 | E19: -5187 | F19: -3345 | G19: -4996
A20: Excise duty on sale of goods/products | B20: — | C20: 594267 | D20: 728548 | E20: 915117 | F20: 1025685 | G20: 1049345
A21: Employee benefits expense | B21: 26/24/25 | C21: 48549 | D21: 52312 | E21: 41183 | F21: 45210 | G21: 52180
A22: Contract employee expense | B22: — | C22: — | D22: — | E22: 18368 | F22: 19525 | G22: 19666
A23: Finance costs | B23: 27/25/26 | C23: 2267 | D23: 1478 | E23: 464 | F23: 689 | G23: 1286
A24: Depreciation and amortisation expense | B24: 28/26/27 | C24: 23201 | D24: 21719 | E24: 21059 | F24: 21190 | G24: 23298
A25: Other expenses | B25: 29/27/28 | C25: 134717 | D25: 169258 | E25: 202282 | F25: 212679 | G25: 228731
A26: Total Expenses | C26: =-SUM(C17:C25) -> -1005938 | D26: =-SUM(D17:D25) -> -1265927 | E26: =-SUM(E17:E25) -> -1625009 | F26: =-SUM(F17:F25) -> -1790213 | G26: =-SUM(G17:G25) -> -1881357
A28: Profit before exceptional items and tax | C28: =SUM(C14,C26) -> 17663 | D28: =SUM(D14,D26) -> 49444 | E28: =SUM(E14,E26) -> 45043 | F28: =SUM(F14,F26) -> 55114 | G28: =SUM(G14,G26) -> 63087
A29: Exceptional items | B29: 30/28/29 | C29: -722 | D29: — | E29: -3312 | F29: — | G29: -2576
A30: Profit before tax | C30: =SUM(C28:C29) -> 16941 | D30: =SUM(D28:D29) -> 49444 | E30: =SUM(E28:E29) -> 41731 | F30: =SUM(F28:F29) -> 55114 | G30: =SUM(G28:G29) -> 60511
A32: Tax Expense
A33: Current tax | B33: 31/29/30 | C33: -6779 | D33: -13203 | E33: -12035 | F33: -14879 | G33: -17731
A34: Deferred tax (credit) | B34: 31/29/30 | C34: 1221 | D34: 367 | E34: 772 | F34: 851 | G34: 1461
A35: Total Tax Expense | C35: =SUM(C33:C34) -> -5558 | D35: =SUM(D33:D34) -> -12836 | E35: =SUM(E33:E34) -> -11263 | F35: =SUM(F33:F34) -> -14028 | G35: =SUM(G33:G34) -> -16270
A36: Profit for the year | C36: =SUM(C35,C30) -> 11383 | D36: =SUM(D35,D30) -> 36608 | E36: =SUM(E35,E30) -> 30468 | F36: =SUM(F35,F30) -> 41086 | G36: =SUM(G35,G30) -> 44241
A38: Other Comprehensive Income (OCI)
A39: Re-measurement gains/(losses) on defined benefit plans | C39: 1991 | D39: 80 | E39: 457 | F39: 232 | G39: 318
A40: Income tax effect on above | C40: -501 | D40: -20 | E40: -115 | F40: -59 | G40: -80
A41: Total OCI | C41: 1490 | D41: 60 | E41: 342 | F41: 173 | G41: 238
A42: Total Comprehensive Income | C42: 12873 | D42: 36668 | E42: 30810 | F42: 41259 | G42: 44479
A44: Profit attributable to:
A45: Equity shareholders of the Holding Company | C45: 11322 | D45: 36546 | E45: 30398 | F45: 41003 | G45: 44169
A46: Non-controlling interest | C46: 61 | D46: 62 | E46: 70 | F46: 83 | G46: 72
A47: Total Profit | C47: 11383 | D47: 36608 | E47: 30468 | F47: 41086 | G47: 44241
A49: OCI attributable to:
A50: Equity shareholders of the Holding Company | C50: 1490 | D50: 60 | E50: 342 | F50: 173 | G50: 238
A51: Non-controlling interest | C51: — | D51: — | E51: — | F51: — | G51: —
A52: Total OCI | C52: 1490 | D52: 60 | E52: 342 | F52: 173 | G52: 238
A54: Total Comprehensive Income attributable to:
...

Sheet Cash flow-Historic
A1: United Breweries Limited
A2: Annual Report- Cash Flow Consolidated
A12: Particulars | B12: FY2021 | C12: FY2022 | D12: FY2023 | E12: FY2024 | F12: FY2025
A13: CASH FLOW FROM OPERATING ACTIVITIES
A14: Profit before tax | B14: 16941 | C14: 49444 | D14: 41731 | E14: 55114 | F14: 60511
A15: Depreciation and amortisation expense | B15: 23201 | C15: 21719 | D15: 21059 | E15: 21190 | F15: 23298
A16: Bad debts/advances written off | B16: 28 | C16: 301 | D16: 0 | E16: 6 | F16: 0
A17: Loss allowance for trade receivables | B17: 479 | C17: 1720 | D17: 818 | E17: 1274 | F17: 1099
A18: Provision for doubtful advances/deposits | B18: 966 | C18: 620 | D18: 181 | E18: 358 | F18: 11
A19: Unrealised exchange differences (net) | B19: -33 | C19: 48 | D19: -148 | E19: 11 | F19: 61
A20: Net gain on disposal of PPE | B20: -4 | C20: -8 | D20: -135 | E20: -37 | F20: -4
A21: Profit on sale of investments | B21: 0 | C21: -54 | D21: 0 | E21: 0 | F21: 0
A22: Liabilities no longer required written back | B22: -205 | C22: -479 | D22: -297 | E22: -730 | F22: 0
A23: Loss allowance no longer required written back | B23: -3380 | C23: -217 | D23: -4 | E23: -50 | F23: 0
A24: Impairment loss on PPE | B24: 4446 | C24: 0 | D24: 3312 | E24: 0 | F24: 0
A25: Impairment loss on goodwill | B25: 1776 | C25: 0 | D25: 0 | E25: 0 | F25: 0
... A39: Net cash from/(used in) operating activities | B39: 62028 | C39: 89962 | D39: -11957 | E39: 6950 | F39: 23505
A41: CASH FLOW FROM INVESTING ACTIVITIES
A42: Purchase of PPE including CWIP, intangible assets and capital advances | B42: -20066 | C42: -17355 | D42: -15628 | E42: -19150 | F42: -25830
A43: Proceeds from sale of PPE | B43: 5091 | C43: 77 | D43: 198 | E43: 82 | F43: 14
A44: Investments in equity and debt securities | B44: -579 | C44: -300 | D44: 0 | E44: -1 | F44: 0
A45: Proceeds from sale of equity and debt securities | B45: 0 | C45: 125 | D45: 30 | E45: 9 | F45: 12
A46: Investments in bank deposits >3 months | B46: -394 | C46: -173 | D46: -616 | E46: -167 | F46: -511
A47: Redemption/maturity of bank deposits >3 months | B47: 335 | C47: 122 | D47: 581 | E47: 61 | F47: 633
A48: Interest received | B48: 458 | C48: 1497 | D48: 3352 | E48: 4385 | F48: 1740
A49: Net cash used in investing activities | B49: -15155 | C49: -16007 | D49: -12083 | E49: -14781 | F49: -23942
A51: CASH FLOW FROM FINANCING ACTIVITIES
A52: Proceeds from long-term borrowings | B52: 25000 | C52: 0 | D52: 0 | E52: 0 | F52: 0
A53: Repayment of long-term borrowings | B53: -7543 | C53: -25000 | D53: 0 | E53: 0 | F53: 0
A54: Repayment of principal portion of lease liabilities | B54: -853 | C54: -492 | D54: -998 | E54: -727 | F54: -953
A55: (Repayment of)/proceeds from short-term borrowings | B55: -15998 | C55: -17 | D55: 0 | E55: 7741 | F55: 49744
A56: Interest paid | B56: -2813 | C56: -1812 | D56: -451 | E56: 598 | F56: -614
A57: Dividend paid | B57: -6610 | C57: -1344 | D57: -27785 | E57: -19852 | F57: -26463
A58: Dividend distribution tax paid | B58: 0 | C58: 0 | D58: 0 | E58: 0 | F58: 0
A59: Net cash from/(used in) financing activities | B59: -8817 | C59: -28665 | D59: -29234 | E59: -12240 | F59: 21714
A61: Net increase/(decrease) in cash and cash equivalents | B61: 38041 | C61: 45290 | D61: -53274 | E61: -20071 | F61: 21277
A62: Cash and cash equivalents at beginning of year | B62: 2899 | C62: 40970 | D62: 86260 | E62: 32986 | F62: 12915
A63: Cash and cash equivalents at end of year | B63: 40940 | C63: 86260 | D63: 32986 | E63: 12915 | F63: 34192

Sheet Assumptions
A1: United Breweries Limited
A2: Assumptions and Forecasts
C3: Period Start | H3: 43922 | I3: 44287 | J3: 44652 | K3: 45017 | L3: 45383 | M3: 45748 | N3: 46113 | O3: 46478 | P3: 46844 | Q3: 47209 | R3: 47574 | S3: 47939 | T3: 48305 | U3: 48670 | V3: 49035
C4: Period End | H4: 44286 | I4: 44651 | J4: 45016 | K4: 45382 | L4: 45747 | M4: 46112 | N4: 46477 | O4: 46843 | P4: 47208 | Q4: 47573 | R4: 47938 | S4: 48304 | T4: 48669 | U4: 49034 | V4: 49399
C5: Period Type | H5: Historical | I5: Historical | J5: Historical | K5: Historical | L5: Historical | M5: Forecast | N5: Forecast | O5: Forecast | P5: Forecast | Q5: Forecast | R5: Forecast | S5: Forecast | T5: Forecast | U5: Forecast | V5: Forecast
C6: Days | H6: =H4-H3+1 -> 365 | I6: =I4-I3+1 -> 365 | J6: =J4-J3+1 -> 365 | K6: =K4-K3+1 -> 366 | L6: =L4-L3+1 -> 365 | M6: =M4-M3+1 -> 365 | N6: =N4-N3+1 -> 365 | O6: =O4-O3+1 -> 366 | ... V6: =V4-V3+1 -> 365
A8: Timing
A10: Model Start Date | B10: Date | C10: 01-Apr-20
A11: Months in a period | B11: # | C11: 12
A12: Start of Forecast Period | B12: Date | C12: 01-Apr-25
A13: Number of Forecast Period | B13: # | C13: 10
A16: Revenue
A17: Revenue from Contracts with Customers
A18: Revenue from Contracts with Customers | B18: ₹ Lakhs | C18: Forecast based on recent historical growth trend, with gradual normalization toward a steady-state growth rate. | H18: ='Income Statement-Historic'!C12 -> 1018576 | I18: ='Income Statement-Historic'!D12 -> 1312392 | J18: ='Income Statement-Historic'!E12 -> 1665109 | K18: ='Income Statement-Historic'!F12 -> 1837953 | L18: ='Income Statement-Historic'!G12 -> 1940854
A19: Revenue Growth Rate | B19: % | I19: =IFERROR(I18/H18-1,"") -> 0.28845761 | J19: =IFERROR(J18/I18-1,"") -> 0.26875888 | K19: =IFERROR(K18/J18-1,"") -> 0.10380341 | L19: =IFERROR(L18/K18-1,"") -> 0.055986742 | M19: 0.07 | N19: 0.07 | O19: 0.065 | P19: 0.065 | Q19: 0.06 | R19: 0.06 | S19: 0.055 | T19: 0.055 | U19: 0.05 | V19: 0.05
A21: Other Income | B21: ₹ Lakhs | H21: ='Income Statement-Historic'!C13 -> 5025 | I21: ='Income Statement-Historic'!D13 -> 2979 | J21: ='Income Statement-Historic'!E13 -> 4943 | K21: ='Income Statement-Historic'!F13 -> 7374 | L21: ='Income Statement-Historic'!G13 -> 3590
A22: Other Income % of Revenue | B22: % | H22: =H21/H18 -> 0.0049333579 | I22: =I21/I18 -> 0.0022699011 | J22: =J21/J18 -> 0.0029685744 | K22: =K21/K18 -> 0.0040120721 | L22: =L21/L18 -> 0.0018497012 | M22: =AVERAGE(H22:L22) -> 0.0032067214 | N22: =M22 -> 0.0032067214 | O22: =N22 -> 0.0032067214 | P22: =O22 -> 0.0032067214 | Q22: =P22 -> 0.0032067214 | R22: =Q22 -> 0.0032067214 | S22: =R22 -> 0.0032067214 | T22: =S22 -> 0.0032067214 | U22: =T22 -> 0.0032067214 | V22: =U22 -> 0.0032067214
A25: Cost
A26: Cost of Sales
A27: Cost of Materials Consumed | B27: ₹ Lakhs | H27: ='Income Statement-Historic'!C17 -> 196516 | I27: ='Income Statement-Historic'!D17 -> 270729 | J27: ='Income Statement-Historic'!E17 -> 422476 | K27: ='Income Statement-Historic'!F17 -> 456755 | L27: ='Income Statement-Historic'!G17 -> 493673
A28: Cost of Materials % of Revenue | B28: % | H28: =H27/H18 -> 0.19293209 | I28: =I27/I18 -> 0.20628669 | J28: =J27/J18 -> 0.25372273 | K28: =K27/K18 -> 0.24851288 | L28: =L27/L18 -> 0.25435865 | M28: ='Working '!M26 -> 0.23116261 | N28: ='Working '!N26 -> 0.22653936 | O28: ='Working '!O26 -> 0.21521239 | P28: ='Working '!P26 -> 0.20660389 | Q28: ='Working '!Q26 -> 0.19833974 | R28: ='Working '!R26 -> 0.19040615 | S28: ='Working '!S26 -> 0.19040615 | T28: ='Working '!T26 -> 0.19040615 | ... V28: ='Working '!V26 -> 0.19040615
A30: Purchase of Stock-in-Trade / Traded Goods | B30: ₹ Lakhs | H30: ='Income Statement-Historic'!C18 -> 7371 | I30: ='Income Statement-Historic'!D18 -> 19582 | J30: ='Income Statement-Historic'!E18 -> 9247 | K30: ='Income Statement-Historic'!F18 -> 11825 | L30: ='Income Statement-Historic'!G18 -> 18174
A31: Purchases % of Revenue | B31: % | H31: =H30/H18 -> 0.0072365734 | I31: =I30/I18 -> 0.014920847 | J31: =J30/J18 -> 0.0055533902 | K31: =K30/K18 -> 0.006433788 | L31: =L30/L18 -> 0.0093639192 | M31: =AVERAGE(H31:L31) -> 0.0087017035 | N31: =M31 -> 0.0087017035 | O31: =N31 -> 0.0087017035 | P31: =O31 -> 0.0087017035 | Q31: =P31 -> 0.0087017035 | R31: =Q31 -> 0.0087017035 | S31: =R31 -> 0.0087017035 | T31: =S31 -> 0.0087017035 | U31: =T31 -> 0.0087017035 | V31: =U31 -> 0.0087017035
A33: Changes in Inventories | B33: ₹ Lakhs | H33: ='Income Statement-Historic'!C19 -> -950 | I33: ='Income Statement-Historic'!D19 -> 2301 | J33: ='Income Statement-Historic'!E19 -> -5187 | K33: ='Income Statement-Historic'!F19 -> -3345 | L33: ='Income Statement-Historic'!G19 -> -4996
A34: Changes in Inventories % of Revenue | B34: % | H34: =H33/H18 -> -0.00093267464 | I34: =I33/I18 -> 0.0017532871 | J34: =J33/J18 -> -0.0031151114 | K34: =K33/K18 -> -0.0018199595 | L34: =L33/L18 -> -0.0025741246 | M34: =AVERAGE(H34:L34) -> -0.0013377166 | N34: =M34 -> -0.0013377166 | O34: =N34 -> -0.0013377166 | P34: =O34 -> -0.0013377166 | Q34: =P34 -> -0.0013377166 | R34: =Q34 -> -0.0013377166 | S34: =R34 -> -0.0013377166 | T34: =S34 -> -0.0013377166 | U34: =T34 -> -0.0013377166 | V34: =U34 -> -0.0013377166
A36: Excise Duty on Sale of Goods/Products | B36: ₹ Lakhs | H36: ='Income Statement-Historic'!C20 -> 594267 | I36: ='Income Statement-Historic'!D20 -> 728548 | J36: ='Income Statement-Historic'!E20 -> 915117 | K36: ='Income Statement-Historic'!F20 -> 1025685 | L36: ='Income Statement-Historic'!G20 -> 1049345
A37: Excise Duty % of Revenue | B37: % | H37: =H36/H18 -> 0.58342922 | I37: =I36/I18 -> 0.55512987 | J37: =J36/J18 -> 0.54958384 | K37: =K36/K18 -> 0.55805834 | L37: =L36/L18 -> 0.54066148 | M37: ='Working '!M32 -> 0.55737255 | N37: ='Working '!N32 -> 0.55737255 | O37: ='Working '!O32 -> 0.55179882 | P37: ='Working '!P32 -> 0.54628084 | Q37: ='Working '!Q32 -> 0.54081803 | R37: ='Working '!R32 -> 0.53540985 | S37: ='Working '!S32 -> 0.53005575 | T37: ='Working '!T32 -> 0.52475519 | ... V37: ='Working '!V32 -> 0.51431256
A39: COGS | B39: ₹ Lakhs | C39: Excise duty is an indirect tax/levy on sales rather than a core operating cost incurred to produce the product; therefore, it is presented separately and excluded from COGS. | H39: =SUM(H33,H30,H27) -> 202937 | I39: =SUM(I33,I30,I27) -> 292612 | J39: =SUM(J33,J30,J27) -> 426536 | K39: =SUM(K33,K30,K27) -> 465235 | L39: =SUM(L33,L30,L27) -> 506851 | M39: ='Working '!M33 -> 492783.8 | N39: ='Working '!N33 -> 517005.42 | O39: ='Working '!O33 -> 523805.28 | P39: ='Working '!P33 -> 536156.26 | Q39: ='Working '!Q33 -> 546247.42 | R39: ='Working '!R33 -> 556555.47 | S39: ='Working '!S33 -> 587166.02 | T39: ='Working '!T33 -> 619460.16 | ... V39: ='Working '!V33 -> 682954.82
A40: COGS % of Revenue | B40: % | H40: =H39/H18 -> 0.19923599 | I40: =I39/I18 -> 0.22296082 | J40: =J39/J18 -> 0.25616101 | K40: =K39/K18 -> 0.25312671 | L40: =L39/L18 -> 0.26114844
A42: Employee Costs
A43: Employee Benefits Expense | B43: ₹ Lakhs | H43: ='Income Statement-Historic'!C21 -> 48549 | I43: ='Income Statement-Historic'!D21 -> 52312 | J43: ='Income Statement-Historic'!E21 -> 41183 | K43: ='Income Statement-Historic'!F21 -> 45210 | L43: ='Income Statement-Historic'!G21 -> 52180
A44: Employee Benefits % of Revenue | B44: % | H44: =H43/H18 -> 0.047663601 | I44: =I43/I18 -> 0.039860042 | J44: =J43/J18 -> 0.024732915 | K44: =K43/K18 -> 0.024598017 | L44: =L43/L18 -> 0.026885072 | M44: =AVERAGE(H44:L44) -> 0.03274793 | N44: =M44 -> 0.03274793 | O44: =N44 -> 0.03274793 | P44: =O44 -> 0.03274793 | Q44: =P44 -> 0.03274793 | R44: =Q44 -> 0.03274793 | S44: =R44 -> 0.03274793 | T44: =S44 -> 0.03274793 | U44: =T44 -> 0.03274793 | V44: =U44 -> 0.03274793
A46: Contract Employee Expense | B46: ₹ Lakhs | H46: ='Income Statement-Historic'!C22 -> — | I46: ='Income Statement-Historic'!D22 -> — | J46: ='Income Statement-Historic'!E22 -> 18368 | K46: ='Income Statement-Historic'!F22 -> 19525 | L46: ='Income Statement-Historic'!G22 -> 19666
A47: Contract Employee % of Revenue | B47: % | H47: =IFERROR([2]Working!H38/[2]Working!H17,"") | I47: =IFERROR([2]Working!I38/[2]Working!I17,"") | J47: =J46/J18 -> 0.01103111 | K47: =K46/K18 -> 0.010623231 | L47: =L46/L18 -> 0.010132653 | M47: =AVERAGE(J47:L47) -> 0.010595665 | N47: =M47 -> 0.010595665 | O47: =N47 -> 0.010595665 | P47: =O47 -> 0.010595665 | Q47: =P47 -> 0.010595665 | R47: =Q47 -> 0.010595665 | S47: =R47 -> 0.010595665 | T47: =S47 -> 0.010595665 | U47: =T47 -> 0.010595665 | V47: =U47 -> 0.010595665
A49: Other Operating Expenses
A50: Other Expenses | B50: ₹ Lakhs | H50: ='Income Statement-Historic'!C25 -> 134717 | I50: ='Income Statement-Historic'!D25 -> 169258 | J50: ='Income Statement-Historic'!E25 -> 202282 | K50: ='Income Statement-Historic'!F25 -> 212679 | L50: ='Income Statement-Historic'!G25 -> 228731
A51: Other Expenses % of Revenue | B51: % | H51: =H50/H18 -> 0.13226014 | I51: =I50/I18 -> 0.12896909 | J51: =J50/J18 -> 0.12148274 | K51: =K50/K18 -> 0.11571515 | L51: =L50/L18 -> 0.1178507 | M51: ='Working '!M43 -> 0.12325556 | N51: ='Working '!N43 -> 0.12325556 | O51: ='Working '!O43 -> 0.12202301 | P51: ='Working '!P43 -> 0.12080278 | Q51: ='Working '!Q43 -> 0.11959475 | R51: ='Working '!R43 -> 0.1183988 | S51: ='Working '!S43 -> 0.11484684 | T51: ='Working '!T43 -> 0.11140143 | ... V51: ='Working '!V43 -> 0.10481761
A53: Finance Cost
A54: Finance Cost | B54: ₹ Lakhs | H54: ='Income Statement-Historic'!C23 -> 2267 | I54: ='Income Statement-Historic'!D23 -> 1478 | J54: ='Income Statement-Historic'!E23 -> 464 | K54: ='Income Statement-Historic'!F23 -> 689 | L54: ='Income Statement-Historic'!G23 -> 1286
A55: Finance Cost % of Revenue | B55: % | H55: =H54/H18 -> 0.0022256562 | I55: =I54/I18 -> 0.0011261879 | J55: =J54/J18 -> 0.00027866044 | K55: =K54/K18 -> 0.00037487357 | L55: =L54/L18 -> 0.00066259492 | M55: =AVERAGE(H55:L55) -> 0.00093359461 | N55: =AVERAGE(I55:M55) -> 0.00067518229 | O55: =AVERAGE(J55:N55) -> 0.00058498116 | P55: =AVERAGE(K55:O55) -> 0.00064624531 | Q55: =AVERAGE(L55:P55) -> 0.00070051966 | R55: =AVERAGE(M55:Q55) -> 0.00070810461 | S55: =AVERAGE(N55:R55) -> 0.00066300661 | T55: =AVERAGE(O55:S55) -> 0.00066057147 | ... V55: =AVERAGE(Q55:U55) -> 0.00068157837
...

Sheet Working 
A1: United Breweries Limited
A2: Working
C3: Period Start | H3: 43922 | I3: 44287 | J3: 44652 | K3: 45017 | L3: 45383 | M3: 45748 | N3: 46113 | O3: 46478 | P3: 46844 | Q3: 47209 | R3: 47574 | S3: 47939 | T3: 48305 | U3: 48670 | V3: 49035
C4: Period End | H4: 44286 | I4: 44651 | J4: 45016 | K4: 45382 | L4: 45747 | M4: 46112 | N4: 46477 | O4: 46843 | P4: 47208 | Q4: 47573 | R4: 47938 | S4: 48304 | T4: 48669 | U4: 49034 | V4: 49399
C5: Period Type | H5: Historical | I5: Historical | J5: Historical | K5: Historical | L5: Historical | M5: Forecast | N5: Forecast | O5: Forecast | P5: Forecast | Q5: Forecast | R5: Forecast | S5: Forecast | T5: Forecast | U5: Forecast | V5: Forecast
C6: Days | H6: =H4-H3+1 -> 365 | I6: =I4-I3+1 -> 365 | J6: =J4-J3+1 -> 365 | K6: =K4-K3+1 -> 366 | L6: =L4-L3+1 -> 365 | M6: =M4-M3+1 -> 365 | N6: =N4-N3+1 -> 365 | O6: =O4-O3+1 -> 366 | ... V6: =V4-V3+1 -> 365
A7: Timing
A9: Model Start Date | B9: Date | C9: 43922
A10: Months in a period | B10: # | C10: 12
A11: Start of Forecast Period | B11: Date | C11: 45748
A12: Number of Forecast Period | B12: # | C12: 10
A15: Revenue
A16: Revenue from Contracts with Customers
A17: Revenue from contracts with customers (including excise duty) | B17: ₹ Lakhs | H17: ='Income Statement-Historic'!C12 -> 1018576 | I17: ='Income Statement-Historic'!D12 -> 1312392 | J17: ='Income Statement-Historic'!E12 -> 1665109 | K17: ='Income Statement-Historic'!F12 -> 1837953 | L17: ='Income Statement-Historic'!G12 -> 1940854 | M17: =L17*(1+M18) -> 2076713.8 | N17: =M17*(1+N18) -> 2222083.7 | O17: =N17*(1+O18) -> 2366519.2 | P17: =O17*(1+P18) -> 2520342.9 | Q17: =P17*(1+Q18) -> 2671563.5 | R17: =Q17*(1+R18) -> 2831857.3 | S17: =R17*(1+S18) -> 2987609.5 | T17: =S17*(1+T18) -> 3151928 | ... V17: =U17*(1+V18) -> 3475000.6
A18: Revenue Growth Rate | B18: % | I18: =I17/H17-1 -> 0.28845761 | J18: =J17/I17-1 -> 0.26875888 | K18: =K17/J17-1 -> 0.10380341 | L18: =L17/K17-1 -> 0.055986742 | M18: 0.07 | N18: 0.07 | O18: 0.065 | P18: 0.065 | Q18: 0.06 | R18: 0.06 | S18: 0.055 | T18: 0.055 | U18: 0.05 | V18: 0.05
A19: Other income | B19: ₹ Lakhs | H19: ='Income Statement-Historic'!C13 -> 5025 | I19: ='Income Statement-Historic'!D13 -> 2979 | J19: ='Income Statement-Historic'!E13 -> 4943 | K19: ='Income Statement-Historic'!F13 -> 7374 | L19: ='Income Statement-Historic'!G13 -> 3590 | M19: =M17*M20 -> 6659.4424 | N19: =N17*N20 -> 7125.6034 | O19: =O17*O20 -> 7588.7676 | P19: =P17*P20 -> 8082.0375 | Q19: =Q17*Q20 -> 8566.9598 | R19: =R17*R20 -> 9080.9774 | S19: =S17*S20 -> 9580.4311 | T19: =T17*T20 -> 10107.355 | ... V19: =V17*V20 -> 11143.359
A20: Other Income % of Revenue | B20: % | H20: =H19/H17 -> 0.0049333579 | I20: =I19/I17 -> 0.0022699011 | J20: =J19/J17 -> 0.0029685744 | K20: =K19/K17 -> 0.0040120721 | L20: =L19/L17 -> 0.0018497012 | M20: =AVERAGE(H20:L20) -> 0.0032067214 | N20: =$M$20 -> 0.0032067214 | O20: =$M$20 -> 0.0032067214 | P20: =$M$20 -> 0.0032067214 | Q20: =$M$20 -> 0.0032067214 | R20: =$M$20 -> 0.0032067214 | S20: =$M$20 -> 0.0032067214 | T20: =$M$20 -> 0.0032067214 | U20: =$M$20 -> 0.0032067214 | V20: =$M$20 -> 0.0032067214
A21: Total Revenue | H21: =SUM(H19,H17) -> 1023601 | I21: =SUM(I19,I17) -> 1315371 | J21: =SUM(J19,J17) -> 1670052 | K21: =SUM(K19,K17) -> 1845327 | L21: =SUM(L19,L17) -> 1944444 | M21: =SUM(M19,M17) -> 2083373.2 | N21: =SUM(N19,N17) -> 2229209.3 | O21: =SUM(O19,O17) -> 2374108 | ... V21: =SUM(V19,V17) -> 3486144
A23: Cost
A24: Cost of Sales
A25: Cost of materials consumed | B25: ₹ Lakhs | H25: ='Income Statement-Historic'!C17 -> 196516 | I25: ='Income Statement-Historic'!D17 -> 270729 | J25: ='Income Statement-Historic'!E17 -> 422476 | K25: ='Income Statement-Historic'!F17 -> 456755 | L25: ='Income Statement-Historic'!G17 -> 493673 | M25: =M17*M26 -> 480058.57 | N25: =N17*N26 -> 503389.42 | O25: =O17*O26 -> 509304.25 | P25: =P17*P26 -> 520712.66 | Q25: =Q17*Q26 -> 529877.21 | R25: =R17*R26 -> 539203.04 | S25: =S17*S26 -> 568859.21 | T25: =T17*T26 -> 600146.47 | ... V25: =V17*V26 -> 661661.48
A26: Cost as % of Revenue | B26: % of Revenue | H26: =H25/H17 -> 0.19293209 | I26: =I25/I17 -> 0.20628669 | J26: =J25/J17 -> 0.25372273 | K26: =K25/K17 -> 0.24851288 | L26: =L25/L17 -> 0.25435865 | M26: =AVERAGE(H26:L26) -> 0.23116261 | N26: =M26-(M26*2%) -> 0.22653936 | O26: =N26-(N26*5%) -> 0.21521239 | P26: =O26-(O26*4%) -> 0.20660389 | Q26: =P26-(P26*4%) -> 0.19833974 | R26: =Q26-(Q26*4%) -> 0.19040615 | S26: =R26 -> 0.19040615 | T26: =S26 -> 0.19040615 | U26: =T26 -> 0.19040615 | V26: =U26 -> 0.19040615
A27: Purchase of stock-in-trade / traded goods | B27: ₹ Lakhs | H27: ='Income Statement-Historic'!C18 -> 7371 | I27: ='Income Statement-Historic'!D18 -> 19582 | J27: ='Income Statement-Historic'!E18 -> 9247 | K27: ='Income Statement-Historic'!F18 -> 11825 | L27: ='Income Statement-Historic'!G18 -> 18174 | M27: =M17*M28 -> 18070.948 | N27: =N17*N28 -> 19335.914 | O27: =O17*O28 -> 20592.748 | P27: =P17*P28 -> 21931.277 | Q27: =Q17*Q28 -> 23247.154 | R27: =R17*R28 -> 24641.983 | S27: =S17*S28 -> 25997.292 | T27: =T17*T28 -> 27427.143 | ... V27: =V17*V28 -> 30238.425
A28: Cost as % of Revenue | B28: % of Revenue | H28: =H27/H17 -> 0.0072365734 | I28: =I27/I17 -> 0.014920847 | J28: =J27/J17 -> 0.0055533902 | K28: =K27/K17 -> 0.006433788 | L28: =L27/L17 -> 0.0093639192 | M28: =AVERAGE(H28:L28) -> 0.0087017035 | N28: =$M$28 -> 0.0087017035 | O28: =$M$28 -> 0.0087017035 | P28: =$M$28 -> 0.0087017035 | Q28: =$M$28 -> 0.0087017035 | R28: =$M$28 -> 0.0087017035 | S28: =$M$28 -> 0.0087017035 | T28: =$M$28 -> 0.0087017035 | U28: =$M$28 -> 0.0087017035 | V28: =$M$28 -> 0.0087017035
A29: Changes in inventories of finished goods, work-in-progress and stock-in-trade | B29: ₹ Lakhs | H29: ='Income Statement-Historic'!C19 -> -950 | I29: ='Income Statement-Historic'!D19 -> 2301 | J29: ='Income Statement-Historic'!E19 -> -5187 | K29: ='Income Statement-Historic'!F19 -> -3345 | L29: ='Income Statement-Historic'!G19 -> -4996 | M29: =M17*M30 -> -5345.72 | N29: =N17*N30 -> -5719.9204 | O29: =O17*O30 -> -6091.7152 | P29: =P17*P30 -> -6487.6767 | Q29: =Q17*Q30 -> -6876.9373 | R29: =R17*R30 -> -7289.5536 | S29: =S17*S30 -> -7690.479 | T29: =T17*T30 -> -8113.4553 | ... V29: =V17*V30 -> -8945.0845
A30: Changes in Inventories as % of Revenue | B30: % of Revenue | H30: =H29/H17 -> -0.00093267464 | I30: =I29/I17 -> 0.0017532871 | J30: =J29/J17 -> -0.0031151114 | K30: =K29/K17 -> -0.0018199595 | L30: =L29/L17 -> -0.0025741246 | M30: =L30 -> -0.0025741246 | N30: =M30 -> -0.0025741246 | O30: =N30 -> -0.0025741246 | P30: =O30 -> -0.0025741246 | Q30: =P30 -> -0.0025741246 | R30: =Q30 -> -0.0025741246 | S30: =R30 -> -0.0025741246 | T30: =S30 -> -0.0025741246 | ... V30: =U30 -> -0.0025741246
A31: Excise duty on sale of goods/products | B31: ₹ Lakhs | H31: ='Income Statement-Historic'!C20 -> 594267 | I31: ='Income Statement-Historic'!D20 -> 728548 | J31: ='Income Statement-Historic'!E20 -> 915117 | K31: ='Income Statement-Historic'!F20 -> 1025685 | L31: ='Income Statement-Historic'!G20 -> 1049345 | M31: =M17*M32 -> 1157503.3 | N31: =N17*N32 -> 1238528.5 | O31: =O17*O32 -> 1305842.5 | P31: =P17*P32 -> 1376815 | Q31: =Q17*Q32 -> 1444829.7 | R31: =R17*R32 -> 1516204.3 | S31: =S17*S32 -> 1583599.6 | T31: =T17*T32 -> 1653990.6 | ... V31: =V17*V32 -> 1787236.5
A32: Excise Duty as % of Revenue | B32: % of Revenue | H32: =H31/H17 -> 0.58342922 | I32: =I31/I17 -> 0.55512987 | J32: =J31/J17 -> 0.54958384 | K32: =K31/K17 -> 0.55805834 | L32: =L31/L17 -> 0.54066148 | M32: =AVERAGE(H32:L32) -> 0.55737255 | N32: =M32 -> 0.55737255 | O32: =N32-(N32*1%) -> 0.55179882 | P32: =O32-(O32*1%) -> 0.54628084 | Q32: =P32-(P32*1%) -> 0.54081803 | R32: =Q32-(Q32*1%) -> 0.53540985 | S32: =R32-(R32*1%) -> 0.53005575 | T32: =S32-(S32*1%) -> 0.52475519 | U32: =T32-(T32*1%) -> 0.51950764 | V32: =U32-(U32*1%) -> 0.51431256
A33: COGS | H33: =SUM(H25+H27+H29) -> 202937 | I33: =SUM(I25+I27+I29) -> 292612 | J33: =SUM(J25+J27+J29) -> 426536 | K33: =SUM(K25+K27+K29) -> 465235 | L33: =SUM(L25+L27+L29) -> 506851 | M33: =SUM(M25+M27+M29) -> 492783.8 | N33: =SUM(N25+N27+N29) -> 517005.42 | O33: =SUM(O25+O27+O29) -> 523805.28 | ... V33: =SUM(V25+V27+V29) -> 682954.82
A35: Employee Costs
A36: Employee benefits expense | B36: ₹ Lakhs | H36: ='Income Statement-Historic'!C21 -> 48549 | I36: ='Income Statement-Historic'!D21 -> 52312 | J36: ='Income Statement-Historic'!E21 -> 41183 | K36: ='Income Statement-Historic'!F21 -> 45210 | L36: ='Income Statement-Historic'!G21 -> 52180 | M36: =M17*M37 -> 68008.077 | N36: =N17*N37 -> 72768.642 | O36: =O17*O37 -> 77498.604 | P36: =P17*P37 -> 82536.013 | Q36: =Q17*Q37 -> 87488.174 | R36: =R17*R37 -> 92737.464 | S36: =S17*S37 -> 97838.025 | T36: =T17*T37 -> 103219.12 | ... V36: =V17*V37 -> 113799.08
A37: Employee Benefits Expense as % of Revenue | B37: % of Revenue | H37: =H36/H17 -> 0.047663601 | I37: =I36/I17 -> 0.039860042 | J37: =J36/J17 -> 0.024732915 | K37: =K36/K17 -> 0.024598017 | L37: =L36/L17 -> 0.026885072 | M37: =AVERAGE(H37:L37) -> 0.03274793 | N37: =M37 -> 0.03274793 | O37: =N37 -> 0.03274793 | P37: =O37 -> 0.03274793 | Q37: =P37 -> 0.03274793 | R37: =Q37 -> 0.03274793 | S37: =R37 -> 0.03274793 | T37: =S37 -> 0.03274793 | U37: =T37 -> 0.03274793 | V37: =U37 -> 0.03274793
A38: Contract employee expense | B38: ₹ Lakhs | H38: ='Income Statement-Historic'!C22 -> — | I38: ='Income Statement-Historic'!D22 -> — | J38: ='Income Statement-Historic'!E22 -> 18368 | K38: ='Income Statement-Historic'!F22 -> 19525 | L38: ='Income Statement-Historic'!G22 -> 19666 | M38: =M17*M39 -> 22004.163 | N38: =N17*N39 -> 23544.454 | O38: =O17*O39 -> 25074.844 | P38: =P17*P39 -> 26704.709 | Q38: =Q17*Q39 -> 28306.991 | R38: =R17*R39 -> 30005.411 | S38: =S17*S39 -> 31655.708 | T38: =T17*T39 -> 33396.772 | ... V38: =V17*V39 -> 36819.941
A39: Contract Employee Expense as % of Revenue | B39: % of Revenue | J39: =J38/J17 -> 0.01103111 | K39: =K38/K17 -> 0.010623231 | L39: =L38/L17 -> 0.010132653 | M39: =AVERAGE(J39:L39) -> 0.010595665 | N39: =M39 -> 0.010595665 | O39: =N39 -> 0.010595665 | P39: =O39 -> 0.010595665 | Q39: =P39 -> 0.010595665 | R39: =Q39 -> 0.010595665 | S39: =R39 -> 0.010595665 | T39: =S39 -> 0.010595665 | U39: =T39 -> 0.010595665 | V39: =U39 -> 0.010595665
A41: Other Operating Expenses
A42: Other expenses | B42: ₹ Lakhs | H42: ='Income Statement-Historic'!C25 -> 134717 | I42: ='Income Statement-Historic'!D25 -> 169258 | J42: ='Income Statement-Historic'!E25 -> 202282 | K42: ='Income Statement-Historic'!F25 -> 212679 | L42: ='Income Statement-Historic'!G25 -> 228731 | M42: =M17*M43 -> 255966.52 | N42: =N17*N43 -> 273884.18 | O42: =O17*O43 -> 288769.78 | P42: =P17*P43 -> 304464.42 | Q42: =Q17*Q43 -> 319504.96 | R42: =R17*R43 -> 335288.51 | S42: =S17*S43 -> 343117.5 | T42: =T17*T43 -> 351129.29 | ... V42: =V17*V43 -> 364241.25
A43: Other Expenses as % of Revenue | B43: % of Revenue | H43: =H42/H17 -> 0.13226014 | I43: =I42/I17 -> 0.12896909 | J43: =J42/J17 -> 0.12148274 | K43: =K42/K17 -> 0.11571515 | L43: =L42/L17 -> 0.1178507 | M43: =AVERAGE(H43:L43) -> 0.12325556 | N43: =M43 -> 0.12325556 | O43: =N43-(N43*1%) -> 0.12202301 | P43: =O43-(O43*1%) -> 0.12080278 | Q43: =P43-(P43*1%) -> 0.11959475 | R43: =Q43-(Q43*1%) -> 0.1183988 | S43: =R43-(R43*3%) -> 0.11484684 | T43: =S43-(S43*3%) -> 0.11140143 | U43: =T43-(T43*3%) -> 0.10805939 | V43: =U43-(U43*3%) -> 0.10481761
A44: Finance Cost
A45: Finance Cost | B45: ₹ Lakhs | H45: ='Income Statement-Historic'!C23 -> 2267 | I45: ='Income Statement-Historic'!D23 -> 1478 | J45: ='Income Statement-Historic'!E23 -> 464 | K45: ='Income Statement-Historic'!F23 -> 689 | L45: ='Income Statement-Historic'!G23 -> 1286 | M45: =M46*M17 -> 1938.8088 | N45: =N46*N17 -> 2074.5254 | O45: =O46*O17 -> 2209.3696 | P45: =P46*P17 -> 2352.9786 | Q45: =Q46*Q17 -> 2494.1573 | R45: =R46*R17 -> 2643.8067 | S45: =S46*S17 -> 2789.2161 | T45: =T46*T17 -> 2942.623 | ... V45: =V46*V17 -> 3244.2418
A46: Finacne cost as % of Revenue | B46: % of Revenue | H46: =H45/H17 -> 0.0022256562 | I46: =I45/I17 -> 0.0011261879 | J46: =J45/J17 -> 0.00027866044 | K46: =K45/K17 -> 0.00037487357 | L46: =L45/L17 -> 0.00066259492 | M46: =AVERAGE(H46:L46) -> 0.00093359461 | N46: =M46 -> 0.00093359461 | O46: =N46 -> 0.00093359461 | P46: =O46 -> 0.00093359461 | Q46: =P46 -> 0.00093359461 | R46: =Q46 -> 0.00093359461 | S46: =R46 -> 0.00093359461 | T46: =S46 -> 0.00093359461 | U46: =T46 -> 0.00093359461 | V46: =U46 -> 0.00093359461
...

Sheet FS
A1: United Breweries Limited
A2: Financial Statements Forecasts
A4: Particulars | B4: Unit | C4: Period Type | D4: FY2021 | E4: FY2022 | F4: FY2023 | G4: FY2024 | H4: FY2025 | I4: FY2026 | J4: FY2027 | K4: FY2028 | L4: FY2029 | M4: FY2030 | N4: FY2031 | O4: FY2032 | P4: FY2033 | Q4: FY2034 | R4: FY2035
D5: Historical | E5: Historical | F5: Historical | G5: Historical | H5: Historical | I5: Forecast | J5: Forecast | K5: Forecast | L5: Forecast | M5: Forecast | N5: Forecast | O5: Forecast | P5: Forecast | Q5: Forecast | R5: Forecast
A7: Profit & Loss Statement
A8: Revenue from contracts with customers (including excise duty) | B8: ₹ Lakhs | D8: ='Income Statement-Historic'!C12 -> 1018576 | E8: ='Income Statement-Historic'!D12 -> 1312392 | F8: ='Income Statement-Historic'!E12 -> 1665109 | G8: ='Income Statement-Historic'!F12 -> 1837953 | H8: ='Income Statement-Historic'!G12 -> 1940854 | I8: ='Working '!M17 -> 2076713.8 | J8: ='Working '!N17 -> 2222083.7 | K8: ='Working '!O17 -> 2366519.2 | L8: ='Working '!P17 -> 2520342.9 | M8: ='Working '!Q17 -> 2671563.5 | N8: ='Working '!R17 -> 2831857.3 | O8: ='Working '!S17 -> 2987609.5 | P8: ='Working '!T17 -> 3151928 | ... R8: ='Working '!V17 -> 3475000.6
A9: Other income | B9: ₹ Lakhs | D9: ='Income Statement-Historic'!C13 -> 5025 | E9: ='Income Statement-Historic'!D13 -> 2979 | F9: ='Income Statement-Historic'!E13 -> 4943 | G9: ='Income Statement-Historic'!F13 -> 7374 | H9: ='Income Statement-Historic'!G13 -> 3590 | I9: ='Working '!M19 -> 6659.4424 | J9: ='Working '!N19 -> 7125.6034 | K9: ='Working '!O19 -> 7588.7676 | L9: ='Working '!P19 -> 8082.0375 | M9: ='Working '!Q19 -> 8566.9598 | N9: ='Working '!R19 -> 9080.9774 | O9: ='Working '!S19 -> 9580.4311 | P9: ='Working '!T19 -> 10107.355 | ... R9: ='Working '!V19 -> 11143.359
A10: Total Income | B10: ₹ Lakhs | D10: ='Income Statement-Historic'!C14 -> 1023601 | E10: ='Income Statement-Historic'!D14 -> 1315371 | F10: ='Income Statement-Historic'!E14 -> 1670052 | G10: ='Income Statement-Historic'!F14 -> 1845327 | H10: ='Income Statement-Historic'!G14 -> 1944444 | I10: =SUM(I8:I9) -> 2083373.2 | J10: =SUM(J8:J9) -> 2229209.3 | K10: =SUM(K8:K9) -> 2374108 | L10: =SUM(L8:L9) -> 2528425 | M10: =SUM(M8:M9) -> 2680130.5 | N10: =SUM(N8:N9) -> 2840938.3 | O10: =SUM(O8:O9) -> 2997189.9 | P10: =SUM(P8:P9) -> 3162035.4 | ... R10: =SUM(R8:R9) -> 3486144
A11: Cost of materials consumed | B11: ₹ Lakhs | D11: ='Income Statement-Historic'!C17 -> 196516 | E11: ='Income Statement-Historic'!D17 -> 270729 | F11: ='Income Statement-Historic'!E17 -> 422476 | G11: ='Income Statement-Historic'!F17 -> 456755 | H11: ='Income Statement-Historic'!G17 -> 493673 | I11: ='Working '!M25 -> 480058.57 | J11: ='Working '!N25 -> 503389.42 | K11: ='Working '!O25 -> 509304.25 | L11: ='Working '!P25 -> 520712.66 | M11: ='Working '!Q25 -> 529877.21 | N11: ='Working '!R25 -> 539203.04 | O11: ='Working '!S25 -> 568859.21 | P11: ='Working '!T25 -> 600146.47 | ... R11: ='Working '!V25 -> 661661.48
A12: Purchase of stock-in-trade / traded goods | B12: ₹ Lakhs | D12: ='Income Statement-Historic'!C18 -> 7371 | E12: ='Income Statement-Historic'!D18 -> 19582 | F12: ='Income Statement-Historic'!E18 -> 9247 | G12: ='Income Statement-Historic'!F18 -> 11825 | H12: ='Income Statement-Historic'!G18 -> 18174 | I12: ='Working '!M27 -> 18070.948 | J12: ='Working '!N27 -> 19335.914 | K12: ='Working '!O27 -> 20592.748 | L12: ='Working '!P27 -> 21931.277 | M12: ='Working '!Q27 -> 23247.154 | N12: ='Working '!R27 -> 24641.983 | O12: ='Working '!S27 -> 25997.292 | P12: ='Working '!T27 -> 27427.143 | ... R12: ='Working '!V27 -> 30238.425
A13: Changes in inventories | B13: ₹ Lakhs | D13: ='Income Statement-Historic'!C19 -> -950 | E13: ='Income Statement-Historic'!D19 -> 2301 | F13: ='Income Statement-Historic'!E19 -> -5187 | G13: ='Income Statement-Historic'!F19 -> -3345 | H13: ='Income Statement-Historic'!G19 -> -4996 | I13: ='Working '!M29 -> -5345.72 | J13: ='Working '!N29 -> -5719.9204 | K13: ='Working '!O29 -> -6091.7152 | L13: ='Working '!P29 -> -6487.6767 | M13: ='Working '!Q29 -> -6876.9373 | N13: ='Working '!R29 -> -7289.5536 | O13: ='Working '!S29 -> -7690.479 | P13: ='Working '!T29 -> -8113.4553 | ... R13: ='Working '!V29 -> -8945.0845
A14: Excise duty on sale of goods/products | B14: ₹ Lakhs | D14: ='Income Statement-Historic'!C20 -> 594267 | E14: ='Income Statement-Historic'!D20 -> 728548 | F14: ='Income Statement-Historic'!E20 -> 915117 | G14: ='Income Statement-Historic'!F20 -> 1025685 | H14: ='Income Statement-Historic'!G20 -> 1049345 | I14: ='Working '!M31 -> 1157503.3 | J14: ='Working '!N31 -> 1238528.5 | K14: ='Working '!O31 -> 1305842.5 | L14: ='Working '!P31 -> 1376815 | M14: ='Working '!Q31 -> 1444829.7 | N14: ='Working '!R31 -> 1516204.3 | O14: ='Working '!S31 -> 1583599.6 | P14: ='Working '!T31 -> 1653990.6 | ... R14: ='Working '!V31 -> 1787236.5
A15: Employee benefits expense | B15: ₹ Lakhs | D15: ='Income Statement-Historic'!C21 -> 48549 | E15: ='Income Statement-Historic'!D21 -> 52312 | F15: ='Income Statement-Historic'!E21 -> 41183 | G15: ='Income Statement-Historic'!F21 -> 45210 | H15: ='Income Statement-Historic'!G21 -> 52180 | I15: ='Working '!M36 -> 68008.077 | J15: ='Working '!N36 -> 72768.642 | K15: ='Working '!O36 -> 77498.604 | L15: ='Working '!P36 -> 82536.013 | M15: ='Working '!Q36 -> 87488.174 | N15: ='Working '!R36 -> 92737.464 | O15: ='Working '!S36 -> 97838.025 | P15: ='Working '!T36 -> 103219.12 | ... R15: ='Working '!V36 -> 113799.08
A16: Contract employee expense | B16: ₹ Lakhs | D16: ='Income Statement-Historic'!C22 -> — | E16: ='Income Statement-Historic'!D22 -> — | F16: ='Income Statement-Historic'!E22 -> 18368 | G16: ='Income Statement-Historic'!F22 -> 19525 | H16: ='Income Statement-Historic'!G22 -> 19666 | I16: ='Working '!M38 -> 22004.163 | J16: ='Working '!N38 -> 23544.454 | K16: ='Working '!O38 -> 25074.844 | L16: ='Working '!P38 -> 26704.709 | M16: ='Working '!Q38 -> 28306.991 | N16: ='Working '!R38 -> 30005.411 | O16: ='Working '!S38 -> 31655.708 | P16: ='Working '!T38 -> 33396.772 | ... R16: ='Working '!V38 -> 36819.941
A17: Finance costs | B17: ₹ Lakhs | D17: ='Income Statement-Historic'!C23 -> 2267 | E17: ='Income Statement-Historic'!D23 -> 1478 | F17: ='Income Statement-Historic'!E23 -> 464 | G17: ='Income Statement-Historic'!F23 -> 689 | H17: ='Income Statement-Historic'!G23 -> 1286 | I17: ='Working '!M45 -> 1938.8088 | J17: ='Working '!N45 -> 2074.5254 | K17: ='Working '!O45 -> 2209.3696 | L17: ='Working '!P45 -> 2352.9786 | M17: ='Working '!Q45 -> 2494.1573 | N17: ='Working '!R45 -> 2643.8067 | O17: ='Working '!S45 -> 2789.2161 | P17: ='Working '!T45 -> 2942.623 | ... R17: ='Working '!V45 -> 3244.2418
A18: Depreciation and amortisation expense | B18: ₹ Lakhs | D18: ='Income Statement-Historic'!C24 -> 23201 | E18: ='Income Statement-Historic'!D24 -> 21719 | F18: ='Income Statement-Historic'!E24 -> 21059 | G18: ='Income Statement-Historic'!F24 -> 21190 | H18: ='Income Statement-Historic'!G24 -> 23298 | I18: ='Working '!M48 -> 31361.449 | J18: ='Working '!N48 -> 33556.751 | K18: ='Working '!O48 -> 35737.939 | L18: ='Working '!P48 -> 38060.905 | M18: ='Working '!Q48 -> 40344.56 | N18: ='Working '!R48 -> 42765.233 | O18: ='Working '!S48 -> 45117.321 | P18: ='Working '!T48 -> 47598.774 | ... R18: ='Working '!V48 -> 52477.648
A19: Other expenses | B19: ₹ Lakhs | D19: ='Income Statement-Historic'!C25 -> 134717 | E19: ='Income Statement-Historic'!D25 -> 169258 | F19: ='Income Statement-Historic'!E25 -> 202282 | G19: ='Income Statement-Historic'!F25 -> 212679 | H19: ='Income Statement-Historic'!G25 -> 228731 | I19: ='Working '!M42 -> 255966.52 | J19: ='Working '!N42 -> 273884.18 | K19: ='Working '!O42 -> 288769.78 | L19: ='Working '!P42 -> 304464.42 | M19: ='Working '!Q42 -> 319504.96 | N19: ='Working '!R42 -> 335288.51 | O19: ='Working '!S42 -> 343117.5 | P19: ='Working '!T42 -> 351129.29 | ... R19: ='Working '!V42 -> 364241.25
A20: Total Expenses | B20: ₹ Lakhs | D20: =SUM(D11:D19) -> 1005938 | E20: =SUM(E11:E19) -> 1265927 | F20: =SUM(F11:F19) -> 1625009 | G20: =SUM(G11:G19) -> 1790213 | H20: =SUM(H11:H19) -> 1881357 | I20: =SUM(I11:I19) -> 2029566.1 | J20: =SUM(J11:J19) -> 2161362.5 | K20: =SUM(K11:K19) -> 2258938.3 | ... R20: =SUM(R11:R19) -> 3040773.5
A21: Profit before exceptional items and tax | B21: ₹ Lakhs | D21: =D10-D20 -> 17663 | E21: =E10-E20 -> 49444 | F21: =F10-F20 -> 45043 | G21: =G10-G20 -> 55114 | H21: =H10-H20 -> 63087 | I21: =I10-I20 -> 53807.144 | J21: =J10-J20 -> 67846.898 | K21: =K10-K20 -> 115169.63 | ... R21: =R10-R20 -> 445370.52
A22: Exceptional items | B22: ₹ Lakhs | D22: -722 | E22: 0 | F22: -3312 | G22: 0 | H22: -2576 | I22: 0 | J22: 0 | K22: 0 | L22: 0 | M22: 0 | N22: 0 | O22: 0 | P22: 0 | Q22: 0 | R22: 0
A23: Profit before tax | B23: ₹ Lakhs | D23: =SUM(D21:D22) -> 16941 | E23: =SUM(E21:E22) -> 49444 | F23: =SUM(F21:F22) -> 41731 | G23: =SUM(G21:G22) -> 55114 | H23: =SUM(H21:H22) -> 60511 | I23: =SUM(I21:I22) -> 53807.144 | J23: =SUM(J21:J22) -> 67846.898 | K23: =SUM(K21:K22) -> 115169.63 | ... R23: =SUM(R21:R22) -> 445370.52
